nohup: ignoring input
2025-04-12 20:16:48,414 - INFO - âœ… Genesis Block already exists in the database.
2025-04-12 20:16:48,415 - INFO - ðŸ¤– Bot is running...
2025-04-12 20:40:51,312 - INFO - Transaction created: Uj1f5ZLY7usoRZomWY6YWauqHBj3v4X7 -> 36FCPInUDJBgHRZ4NkuPVs5kpccA0YQF (10.0)
2025-04-12 20:42:07,303 - INFO - Transaction created: Uj1f5ZLY7usoRZomWY6YWauqHBj3v4X7 -> 36FCPInUDJBgHRZ4NkuPVs5kpccA0YQF (0.0)
2025-04-12 20:42:28,906 - INFO - New wallet created: WLDHgnRL6d7ZWu9CFbMigSlk7sQpTyia
2025-04-12 20:42:48,193 - INFO - Block mined: 000099d13f0a5c7791e43b23467037209cb77aff2abc0d81c73ef4aa5f5399c9
2025-04-12 20:44:24,630 - INFO - New wallet created: JS2P2agYgxewtwqiAzVwYtM03QRYS4qQ
2025-04-12 20:48:26,234 - INFO - Transaction created: JS2P2agYgxewtwqiAzVwYtM03QRYS4qQ -> WLDHgnRL6d7ZWu9CFbMigSlk7sQpTyia (0.0)
Traceback (most recent call last):
  File "/data/data/com.termux/files/usr/lib/python3.12/site-packages/urllib3/connectionpool.py", line 787, in urlopen
    response = self._make_request(
               ^^^^^^^^^^^^^^^^^^^
  File "/data/data/com.termux/files/usr/lib/python3.12/site-packages/urllib3/connectionpool.py", line 534, in _make_request
    response = conn.getresponse()
               ^^^^^^^^^^^^^^^^^^
  File "/data/data/com.termux/files/usr/lib/python3.12/site-packages/urllib3/connection.py", line 516, in getresponse
    httplib_response = super().getresponse()
                       ^^^^^^^^^^^^^^^^^^^^^
  File "/data/data/com.termux/files/usr/lib/python3.12/http/client.py", line 1430, in getresponse
    response.begin()
  File "/data/data/com.termux/files/usr/lib/python3.12/http/client.py", line 331, in begin
    version, status, reason = self._read_status()
                              ^^^^^^^^^^^^^^^^^^^
  File "/data/data/com.termux/files/usr/lib/python3.12/http/client.py", line 300, in _read_status
    raise RemoteDisconnected("Remote end closed connection without"
http.client.RemoteDisconnected: Remote end closed connection without response

During handling of the above exception, another exception occurred:

Traceback (most recent call last):
  File "/data/data/com.termux/files/usr/lib/python3.12/site-packages/requests/adapters.py", line 667, in send
    resp = conn.urlopen(
           ^^^^^^^^^^^^^
  File "/data/data/com.termux/files/usr/lib/python3.12/site-packages/urllib3/connectionpool.py", line 841, in urlopen
    retries = retries.increment(
              ^^^^^^^^^^^^^^^^^^
  File "/data/data/com.termux/files/usr/lib/python3.12/site-packages/urllib3/util/retry.py", line 474, in increment
    raise reraise(type(error), error, _stacktrace)
          ^^^^^^^^^^^^^^^^^^^^^^^^^^^^^^^^^^^^^^^^
  File "/data/data/com.termux/files/usr/lib/python3.12/site-packages/urllib3/util/util.py", line 38, in reraise
    raise value.with_traceback(tb)
  File "/data/data/com.termux/files/usr/lib/python3.12/site-packages/urllib3/connectionpool.py", line 787, in urlopen
    response = self._make_request(
               ^^^^^^^^^^^^^^^^^^^
  File "/data/data/com.termux/files/usr/lib/python3.12/site-packages/urllib3/connectionpool.py", line 534, in _make_request
    response = conn.getresponse()
               ^^^^^^^^^^^^^^^^^^
  File "/data/data/com.termux/files/usr/lib/python3.12/site-packages/urllib3/connection.py", line 516, in getresponse
    httplib_response = super().getresponse()
                       ^^^^^^^^^^^^^^^^^^^^^
  File "/data/data/com.termux/files/usr/lib/python3.12/http/client.py", line 1430, in getresponse
    response.begin()
  File "/data/data/com.termux/files/usr/lib/python3.12/http/client.py", line 331, in begin
    version, status, reason = self._read_status()
                              ^^^^^^^^^^^^^^^^^^^
  File "/data/data/com.termux/files/usr/lib/python3.12/http/client.py", line 300, in _read_status
    raise RemoteDisconnected("Remote end closed connection without"
urllib3.exceptions.ProtocolError: ('Connection aborted.', RemoteDisconnected('Remote end closed connection without response'))

During handling of the above exception, another exception occurred:

Traceback (most recent call last):
  File "/data/data/com.termux/files/home/python/blockchain/telegram_blockchain_bot.py", line 384, in <module>
    main()
  File "/data/data/com.termux/files/home/python/blockchain/telegram_blockchain_bot.py", line 260, in main
    updates = get_updates(offset)
              ^^^^^^^^^^^^^^^^^^^
  File "/data/data/com.termux/files/home/python/blockchain/telegram_blockchain_bot.py", line 21, in get_updates
    response = requests.get(URL + "getUpdates", params={"offset": offset})
               ^^^^^^^^^^^^^^^^^^^^^^^^^^^^^^^^^^^^^^^^^^^^^^^^^^^^^^^^^^^
  File "/data/data/com.termux/files/usr/lib/python3.12/site-packages/requests/api.py", line 73, in get
    return request("get", url, params=params, **kwargs)
           ^^^^^^^^^^^^^^^^^^^^^^^^^^^^^^^^^^^^^^^^^^^^
  File "/data/data/com.termux/files/usr/lib/python3.12/site-packages/requests/api.py", line 59, in request
    return session.request(method=method, url=url, **kwargs)
           ^^^^^^^^^^^^^^^^^^^^^^^^^^^^^^^^^^^^^^^^^^^^^^^^^
  File "/data/data/com.termux/files/usr/lib/python3.12/site-packages/requests/sessions.py", line 589, in request
    resp = self.send(prep, **send_kwargs)
           ^^^^^^^^^^^^^^^^^^^^^^^^^^^^^^
  File "/data/data/com.termux/files/usr/lib/python3.12/site-packages/requests/sessions.py", line 703, in send
    r = adapter.send(request, **kwargs)

        ^^^^^^^^^^^^^^^^^^^^^^^^^^^^^^^
  File "/data/data/com.termux/files/usr/lib/python3.12/site-packages/requests/adapters.py", line 682, in send
    raise ConnectionError(err, request=request)
requests.exceptions.ConnectionError: ('Connection aborted.', RemoteDisconnected('Remote end closed connection without response'))
